<!DOCTYPE html>
<html lang="en">
<head>
    <meta charset="UTF-8">
    <title>10.1 try-catch</title>
</head>
<body>
<script>
    try {

        console.log('Начало блока try');  // (1) <--

        lalala; // ошибка, переменная не определена!

        console.log('Конец блока try (никогда не выполнится)');  // (2)

    } catch(err) {

        console.log(`Возникла ошибка!`); // (3) <--

    }

    /**
     * Исключение, которое произойдёт в коде, запланированном «на будущее», например в setTimeout, try..catch не поймает:
     */
    // try {
    //     setTimeout(function() {
    //         noSuchVariable; // скрипт упадёт тут
    //     }, 1000);
    // } catch (e) {
    //     alert( "не сработает" );
    // }


    // setTimeout(function() {
    //     try {
    //         noSuchVariable; // try..catch обрабатывает ошибку!
    //     } catch {
    //         alert( "ошибка поймана!" );
    //     }
    // }, 1000);


    try {
        lalala; // ошибка, переменная не определена!
    } catch(err) {
        console.log(err.name); // ReferenceError
        console.log(err.message); // lalala is not defined
        console.log(err.stack); // ReferenceError: lalala is not defined at (...стек вызовов)

        // Можем также просто вывести ошибку целиком
        // Ошибка приводится к строке вида "name: message"
        console.log(err); // ReferenceError: lalala is not defined
    }


    let json = "{ некорректный JSON }";

    try {

        let user = JSON.parse(json); // <-- тут возникает ошибка...
        alert( user.name ); // не сработает

    } catch (e) {
        // ...выполнение прыгает сюда
        console.log( "Извините, в данных ошибка, мы попробуем получить их ещё раз." );
        console.log( e.name );
        console.log( e.message );
    }


    let error = new Error(" Ого, ошибка! o_O");

    console.log(error.name); // Error
    console.log(error.message); //  Ого, ошибка! o_O


    try {
        JSON.parse("{ bad json o_O }");
    } catch(e) {
        console.log(e.name); // SyntaxError
        console.log(e.message); // Unexpected token b in JSON at position 2
    }


    json = '{ "age": 30 }'; // данные неполны

    try {

        let user = JSON.parse(json); // <-- выполнится без ошибок

        if (!user.name) {
            throw new SyntaxError("Данные неполны: нет имени"); // (*)
        }

        console.log( user.name );

    } catch(e) {
        console.log( "JSON Error: " + e.message ); // JSON Error: Данные неполны: нет имени
    }



    function readData() {
        let json = '{ "age": 30 }';

        try {
            // ...
            blabla(); // ошибка!
        } catch (e) {
            // ...
            if (e.name != 'SyntaxError') {
                throw e; // проброс исключения (не знаю как это обработать)
            }
        }
    }

    try {
        readData();
    } catch (e) {
        console.log( "Внешний catch поймал: " + e ); // поймал!
    }




    try {
        console.log( 'try' );
        if (confirm('Сгенерировать ошибку?')) BAD_CODE();
    } catch (e) {
        console.log( 'catch' );
    } finally {
        console.log( 'finally' );
    }




    let num = +prompt("Введите положительное целое число?", 35)

    let diff, result;

    function fib(n) {
        if (n < 0 || Math.trunc(n) != n) {
            throw new Error("Должно быть целое неотрицательное число");
        }
        return n <= 1 ? n : fib(n - 1) + fib(n - 2);
    }

    let start = Date.now();

    try {
        result = fib(num);
    } catch (e) {
        result = 0;
    } finally {
        diff = Date.now() - start;
    }

    console.log(result || "возникла ошибка");

    console.log( `Выполнение заняло ${diff}ms` );



    function func() {

        try {
            return 1;

        } catch (e) {
            /* ... */
        } finally {
            alert( 'finally' );
        }
    }

    alert( func() );
</script>
</body>
</html>